Workbook

Sheet RC GP
AN1: Accumulated | AP1: Ordinary Dep
AD4: in years | AE4: in Months | AH4: in years | AI4: in days
A5: Company Code | B5: External/Legacy Asset Number* External/legacy asset ID. It is an unique number that identifies a fixed asset in the Legacy System. Please note: In S/4HANA Cloud only INTERNAL number assignment is supported. The legacy asset number is migrated to the field "Original Asset" in the tab "Origin" for reference. Key fields are mandatory and must always be filled with a unique key. If there is internal numbering, you can provide the key of your source system or any other unique key. The key is technically mandatory for the tool to internally connect the records of subordinated sheets with the records of the superordinated sheets. Type: Text Length: 12 | C5: Asset number | D5: Main Asset Legacy Number | E5: Asset Subnumber* Must be "0", when migrating a MAIN asset source file. Must be a sequential number (unequal "0"), when migrating an asset subnumber source file (max. 4-digits). The asset subnumber is migrated to the field "Original Asset Subnumber" in the tab "Origin" for reference. This is the number which, together with the main asset number, uniquely identifies a fixed asset in Asset Accounting. Using the asset sub-number, you can: - Provide for separate management of later acquisitions to assets. - Represent complex fixed assets with their component parts. Type: Text Length: 4 | F5: Asset Class* Note: Ensure that the subasset has the same asset class than the main asset. Type: Text Length: 80 | G5: Asset Class in SAP | I5: PM Sheet Maped Cost Center | J5: Cost Center Code | K5: Equipment ID | L5: Asset Description* Asset Description Type: Text Length: 50 | M5: Asset Description 2 Additional Asset description. Type: Text Length: 50 | N5: Serial Number You can enter the manufacturer's serial number in this field. Type: Text Length: 18 | O5: Quantity Quantity Type: Number Length: 13 Decimal: 3 | P5: Base Unit of Measure Base Unit of Measure, for example: KG, KM, TON... Type: Text Length: 80 | Q5: Asset is managed historically Set this indicator to 'X', if the asset is managed historically. Type: Text Length: 1 | R5: Asset Main Number Text In this field, you can enter any desired name for an asset main number. The text is then used, for example, in reporting, and in the display values transaction when accessing totals per asset main number. Type: Text Length: 50 | S5: Original Purchase Date | T5: Asset Capitalization Date* Reference date of the posting that leads to asset being capitalized. Type: Date | U5: Deactivation Date Asset value date of the retirement posting for a full retirement in this field. Type: Date | V5: Plant The Plant is mandatory for migrating an Asset Location. Without indicating the Plant the Asset Location cannot be determined. Type: Text Length: 80 | W5: Asset Location Migrating an Asset Location, the indication of the Plant is mandatory. Without a plant the Asset Location cannot be determined. Type: Text Length: 80 | X5: License Plate No. of Vehicle You can enter the license plate number for a vehicle here. Your entry is saved as time-dependent data, so that a history is created when there is a change in the license plate number. Type: Text Length: 15 | Y5: Fiscal Year of Original Acquisition Fiscal year in which the asset was originally acquired (before the asset transfer). This field is not automatically filled; you need to supply it. Type: Number Length: 4 | Z5: Original Acquisition Value Acquisition value of the asset before the asset transfer. This field is not automatically filled; you need to supply it. Type: Number Length: 23 Decimal: 2 | AA5: Depreciation Area* Depreciation area, which is managed in the system as a real depreciation area (not a derived depreciation area). Type: Text Length: 80 | AB5: Depreciation Key* Depreciation keys are defined at the level of the chart of depreciation. Type: Text Length: 80 | AC5: Life of Assets as per Co's Act | AD5: Useful Life (in years) The two fields ‘Useful Life (in years)’ and ‘Useful Life (in periods)’ are additive. For example, a useful life of 3.5 years would be maintained as ‘Useful Life (in years)’ = 3 and ‘Useful Life (in periods)’ = 6. Type: Number Length: 3 | AE5: Useful Life (in periods) The two fields ‘Useful Life (in years)’ and ‘Useful Life (in periods)’ are additive. For example, a useful life of 3.5 years would be maintained as ‘Useful Life (in years)’ = 3 and ‘Useful Life (in periods)’ = 6. Type: Number Length: 3 | AG5: Used life | AH5: Exp. usef. life in years at start of FY The portion of the useful life of the asset that has already expired. Type: Number Length: 3 | AI5: Exp. usef. life in perio. at start of FY The portion of the useful life of the asset that has already expired. Type: Number Length: 3 | AJ5: Asset Scrap Value You can specify an absolute amount here which cannot be depreciated in this depreciation area (memo value). If you specify a value here, then the cut-off value percentage determined on the basis of the cut-off value key in the depreciation key will not be taken into account. Even if no cut-off key is defined, depreciation will stop when this value is reached. Depending on how the cut-off value key is defined, this amount is either deducted from the depreciation base value before the start of depreciation, or depreciation is stopped as soon as this amount is reached. Type: Number Length: 23 Decimal: 2 | AK5: Scrap Value as Percentage of APC Type: Number Length: 14 Decimal: 11 | AL5: Cumulated Acquisition Value Please enter one row for each depreciation area. Type: Number Length: 23 Decimal: 2 | AN5: Accumulated Ordinary Depreciation Must be negative, e.g. -1267,00, in most of the business cases. Type: Number Length: 23 Decimal: 2 | AP5: Posted Ordinary Deprec. for the Year Depreciation values must be negative, e.g. -1234,56 and corrections of depreciation values positve, e.g. 1234,56. Type: Number Length: 23 Decimal: 2
A6: INO1 | B6: 1131400080 | E6: 0 | F6: 9001 | G6: Factory Building | H6: 9001000001 | I6: Buildings & Admin | J6: 1202010202 | L6: Factory Building-1 | O6: 1 | P6: EA | Q6: X | S6: 38078 | T6: 43191 | Y6: 2018 | Z6: 6450000 | AA6: 01 | AB6: ZSLM | AC6: 5840 | AD6: 16 | AE6: 0 | AG6: =_xlfn.CONCAT(AH6," years ",AI6," days") -> 6 years 277 days | AH6: 6 | AI6: 277 | AJ6: 0 | AK6: 0 | AL6: 6450000 | AM6: =ROUND(AL6,2) -> 6450000 | AN6: 2724683 | AO6: =ROUND(AN6,2)*-1 -> -2724683 | AP6: 199906.04 | AQ6: =ROUND(AP6,2)*-1 -> -199906.04
A7: INO1 | B7: 1131400212 | E7: 0 | F7: 9001 | G7: Factory Building | H7: 9001000001 | I7: Buildings & Admin | J7: 1202010202 | L7: Factory Building-2 | O7: 1 | P7: EA | Q7: X | S7: 39142 | T7: 43191 | Y7: 2018 | Z7: 5025000 | AA7: 01 | AB7: ZSLM | AC7: 6899 | AD7: 18 | AE7: 11 | AG7: =_xlfn.CONCAT(AH7," years ",AI7," days") -> 6 years 277 days | AH7: 6 | AI7: 277 | AJ7: 0 | AK7: 0 | AL7: 5025000 | AM7: =ROUND(AL7,2) -> 5025000 | AN7: 1796880 | AO7: =ROUND(AN7,2)*-1 -> -1796880 | AP7: 131834.31 | AQ7: =ROUND(AP7,2)*-1 -> -131834.31
A8: INO1 | B8: 1131400574 | E8: 0 | F8: 9001 | G8: Factory Building | H8: 9001000001 | I8: Buildings & Admin | J8: 1202010202 | L8: Factory Building-3 | O8: 1 | P8: EA | Q8: X | S8: 40574 | T8: 43191 | Y8: 2018 | Z8: 1400000 | AA8: 01 | AB8: ZSLM | AC8: 8322 | AD8: 22 | AE8: 10 | AG8: =_xlfn.CONCAT(AH8," years ",AI8," days") -> 6 years 277 days | AH8: 6 | AI8: 277 | AJ8: 0 | AK8: 0 | AL8: 1400000 | AM8: =ROUND(AL8,2) -> 1400000 | AN8: 415020 | AO8: =ROUND(AN8,2)*-1 -> -415020 | AP8: 30449.839 | AQ8: =ROUND(AP8,2)*-1 -> -30449.84
A9: INO1 | B9: 1131400670 | E9: 0 | F9: 9001 | G9: Factory Building | H9: 9001000001 | I9: Buildings & Admin | J9: 1202010202 | L9: Factory Building-4 | O9: 1 | P9: EA | Q9: X | S9: 40847 | T9: 43191 | Y9: 2018 | Z9: 2575000 | AA9: 01 | AB9: ZSLM | AC9: 8614 | AD9: 23 | AE9: 7 | AG9: =_xlfn.CONCAT(AH9," years ",AI9," days") -> 6 years 277 days | AH9: 6 | AI9: 277 | AJ9: 0 | AK9: 0 | AL9: 2575000 | AM9: =ROUND(AL9,2) -> 2575000 | AN9: 737465 | AO9: =ROUND(AN9,2)*-1 -> -737465 | AP9: 54106.86 | AQ9: =ROUND(AP9,2)*-1 -> -54106.86
A10: INO1 | B10: 1131400713 | E10: 0 | F10: 9001 | G10: Factory Building | H10: 9001000001 | I10: Buildings & Admin | J10: 1202010202 | L10: Factory Building-5 | O10: 1 | P10: EA | Q10: X | S10: 40999 | T10: 43191 | Y10: 2018 | Z10: 3250000 | AA10: 01 | AB10: ZSLM | AC10: 8760 | AD10: 24 | AE10: 0 | AG10: =_xlfn.CONCAT(AH10," years ",AI10," days") -> 6 years 277 days | AH10: 6 | AI10: 277 | AJ10: 0 | AK10: 0 | AL10: 3250000 | AM10: =ROUND(AL10,2) -> 3250000 | AN10: 915268 | AO10: =ROUND(AN10,2)*-1 -> -915268 | AP10: 67152.091 | AQ10: =ROUND(AP10,2)*-1 -> -67152.09
A11: INO1 | B11: 1131400975 | E11: 0 | F11: 9001 | G11: Factory Building | H11: 9001000001 | I11: Buildings & Admin | J11: 1202010202 | L11: Factory Building-6 | O11: 1 | P11: EA | Q11: X | S11: 41364 | T11: 43191 | Y11: 2018 | Z11: 16925000 | AA11: 01 | AB11: ZSLM | AC11: 9125 | AD11: 25 | AE11: 0 | AG11: =_xlfn.CONCAT(AH11," years ",AI11," days") -> 6 years 277 days | AH11: 6 | AI11: 277 | AJ11: 0 | AK11: 0 | AL11: 16925000 | AM11: =ROUND(AL11,2) -> 16925000 | AN11: 4575778 | AO11: =ROUND(AN11,2)*-1 -> -4575778 | AP11: 335717.89 | AQ11: =ROUND(AP11,2)*-1 -> -335717.89
A12: INO1 | B12: 1131401678 | E12: 0 | F12: 9001 | G12: Factory Building | H12: 9001000001 | I12: Buildings & Admin | J12: 1202010202 | L12: Toilet Line Orrisa Pan Fitting with Pipe Lin-7 | M12: e Complete | O12: 4 | P12: EA | Q12: X | S12: 42217 | T12: 43191 | Y12: 2018 | Z12: 55000 | AA12: 01 | AB12: ZSLM | AC12: 9965 | AD12: 27 | AE12: 4 | AG12: =_xlfn.CONCAT(AH12," years ",AI12," days") -> 6 years 277 days | AH12: 6 | AI12: 277 | AJ12: 0 | AK12: 0 | AL12: 55000 | AM12: =ROUND(AL12,2) -> 55000 | AN12: 13616 | AO12: =ROUND(AN12,2)*-1 -> -13616 | AP12: 999.15304 | AQ12: =ROUND(AP12,2)*-1 -> -999.15
A13: INO1 | B13: 1131100078 | E13: 0 | F13: 9001 | G13: Factory Building | H13: 9001000001 | I13: Buildings & Admin | J13: 1202010202 | L13: Factory Building-8 | O13: 1 | P13: EA | Q13: X | S13: 38078 | T13: 43191 | Y13: 2018 | Z13: 22975000 | AA13: 01 | AB13: ZSLM | AC13: 5840 | AD13: 16 | AE13: 0 | AG13: =_xlfn.CONCAT(AH13," years ",AI13," days") -> 6 years 277 days | AH13: 6 | AI13: 277 | AJ13: 0 | AK13: 0 | AL13: 22975000 | AM13: =ROUND(AL13,2) -> 22975000 | AN13: 9705364 | AO13: =ROUND(AN13,2)*-1 -> -9705364 | AP13: 712067.51 | AQ13: =ROUND(AP13,2)*-1 -> -712067.51
A14: INO1 | B14: 1131100083 | E14: 0 | F14: 9001 | G14: Factory Building | H14: 9001000001 | I14: Buildings & Admin | J14: 1202010202 | L14: Factory Building-9 | O14: 1 | P14: EA | Q14: X | S14: 38107 | T14: 43191 | Y14: 2018 | Z14: 130000 | AA14: 01 | AB14: ZSLM | AC14: 5877 | AD14: 16 | AE14: 1 | AG14: =_xlfn.CONCAT(AH14," years ",AI14," days") -> 6 years 277 days | AH14: 6 | AI14: 277 | AJ14: 0 | AK14: 0 | AL14: 130000 | AM14: =ROUND(AL14,2) -> 130000 | AN14: 54570 | AO14: =ROUND(AN14,2)*-1 -> -54570 | AP14: 4004.1024 | AQ14: =ROUND(AP14,2)*-1 -> -4004.1
A15: INO1 | B15: 1131100087 | E15: 0 | F15: 9001 | G15: Factory Building | H15: 9001000001 | I15: Buildings & Admin | J15: 1202010202 | L15: Factory Building-10 | O15: 1 | P15: EA | Q15: X | S15: 38138 | T15: 43191 | Y15: 2018 | Z15: 390000 | AA15: 01 | AB15: ZSLM | AC15: 5913 | AD15: 16 | AE15: 2 | AG15: =_xlfn.CONCAT(AH15," years ",AI15," days") -> 6 years 277 days | AH15: 6 | AI15: 277 | AJ15: 0 | AK15: 0 | AL15: 390000 | AM15: =ROUND(AL15,2) -> 390000 | AN15: 162714 | AO15: =ROUND(AN15,2)*-1 -> -162714 | AP15: 11938.461 | AQ15: =ROUND(AP15,2)*-1 -> -11938.46
A16: INO1 | B16: 1131100092 | E16: 0 | F16: 9001 | G16: Factory Building | H16: 9001000001 | I16: Buildings & Admin | J16: 1202010202 | L16: Factory Building-11 | O16: 1 | P16: EA | Q16: X | S16: 38168 | T16: 43191 | Y16: 2018 | Z16: 105000 | AA16: 01 | AB16: ZSLM | AC16: 5913 | AD16: 16 | AE16: 2 | AG16: =_xlfn.CONCAT(AH16," years ",AI16," days") -> 6 years 277 days | AH16: 6 | AI16: 277 | AJ16: 0 | AK16: 0 | AL16: 105000 | AM16: =ROUND(AL16,2) -> 105000 | AN16: 43808 | AO16: =ROUND(AN16,2)*-1 -> -43808 | AP16: 3213.8163 | AQ16: =ROUND(AP16,2)*-1 -> -3213.82
A17: INO1 | B17: 1131100094 | E17: 0 | F17: 9001 | G17: Factory Building | H17: 9001000001 | I17: Buildings & Admin | J17: 1202010202 | L17: Factory Building-12 | O17: 1 | P17: EA | Q17: X | S17: 38220 | T17: 43191 | Y17: 2018 | Z17: 530000 | AA17: 01 | AB17: ZSLM | AC17: 5986 | AD17: 16 | AE17: 5 | AG17: =_xlfn.CONCAT(AH17," years ",AI17," days") -> 6 years 277 days | AH17: 6 | AI17: 277 | AJ17: 0 | AK17: 0 | AL17: 530000 | AM17: =ROUND(AL17,2) -> 530000 | AN17: 218428 | AO17: =ROUND(AN17,2)*-1 -> -218428 | AP17: 16025.725 | AQ17: =ROUND(AP17,2)*-1 -> -16025.73
A18: INO1 | B18: 1131100100 | E18: 0 | F18: 9001 | G18: Factory Building | H18: 9001000001 | I18: Buildings & Admin | J18: 1202010202 | L18: Factory Building-13 | O18: 1 | P18: EA | Q18: X | S18: 38260 | T18: 43191 | Y18: 2018 | Z18: 520000 | AA18: 01 | AB18: ZSLM | AC18: 6023 | AD18: 16 | AE18: 6 | AG18: =_xlfn.CONCAT(AH18," years ",AI18," days") -> 6 years 277 days | AH18: 6 | AI18: 277 | AJ18: 0 | AK18: 0 | AL18: 520000 | AM18: =ROUND(AL18,2) -> 520000 | AN18: 212990 | AO18: =ROUND(AN18,2)*-1 -> -212990 | AP18: 15626.968 | AQ18: =ROUND(AP18,2)*-1 -> -15626.97
A19: INO1 | B19: 1131100110 | E19: 0 | F19: 9001 | G19: Factory Building | H19: 9001000001 | I19: Buildings & Admin | J19: 1202010202 | L19: Factory Building-14 | O19: 1 | P19: EA | Q19: X | S19: 38352 | T19: 43191 | Y19: 2018 | Z19: 160000 | AA19: 01 | AB19: ZSLM | AC19: 6096 | AD19: 16 | AE19: 9 | AG19: =_xlfn.CONCAT(AH19," years ",AI19," days") -> 6 years 277 days | AH19: 6 | AI19: 277 | AJ19: 0 | AK19: 0 | AL19: 160000 | AM19: =ROUND(AL19,2) -> 160000 | AN19: 64751 | AO19: =ROUND(AN19,2)*-1 -> -64751 | AP19: 4750.3123 | AQ19: =ROUND(AP19,2)*-1 -> -4750.31
A20: INO1 | B20: 1131100116 | E20: 0 | F20: 9001 | G20: Factory Building | H20: 9001000001 | I20: Buildings & Admin | J20: 1202010202 | L20: Factory Building-15 | O20: 1 | P20: EA | Q20: X | S20: 38383 | T20: 43191 | Y20: 2018 | Z20: 115000 | AA20: 01 | AB20: ZSLM | AC20: 6132 | AD20: 16 | AE20: 10 | AG20: =_xlfn.CONCAT(AH20," years ",AI20," days") -> 6 years 277 days | AH20: 6 | AI20: 277 | AJ20: 0 | AK20: 0 | AL20: 115000 | AM20: =ROUND(AL20,2) -> 115000 | AN20: 46266 | AO20: =ROUND(AN20,2)*-1 -> -46266 | AP20: 3394.7958 | AQ20: =ROUND(AP20,2)*-1 -> -3394.8
A21: INO1 | B21: 1131100119 | E21: 0 | F21: 9001 | G21: Factory Building | H21: 9001000001 | I21: Buildings & Admin | J21: 1202010202 | L21: Factory Building-16 | O21: 1 | P21: EA | Q21: X | S21: 38411 | T21: 43191 | Y21: 2018 | Z21: 630000 | AA21: 01 | AB21: ZSLM | AC21: 6169 | AD21: 16 | AE21: 11 | AG21: =_xlfn.CONCAT(AH21," years ",AI21," days") -> 6 years 277 days | AH21: 6 | AI21: 277 | AJ21: 0 | AK21: 0 | AL21: 630000 | AM21: =ROUND(AL21,2) -> 630000 | AN21: 251939 | AO21: =ROUND(AN21,2)*-1 -> -251939 | AP21: 18484.083 | AQ21: =ROUND(AP21,2)*-1 -> -18484.08
A22: INO1 | B22: 1131100122 | E22: 0 | F22: 9001 | G22: Factory Building | H22: 9001000001 | I22: Buildings & Admin | J22: 1202010202 | L22: Factory Building-17 | O22: 1 | P22: EA | Q22: X | S22: 38442 | T22: 43191 | Y22: 2018 | Z22: 540000 | AA22: 01 | AB22: ZSLM | AC22: 6205 | AD22: 17 | AE22: 0 | AG22: =_xlfn.CONCAT(AH22," years ",AI22," days") -> 6 years 277 days | AH22: 6 | AI22: 277 | AJ22: 0 | AK22: 0 | AL22: 540000 | AM22: =ROUND(AL22,2) -> 540000 | AN22: 214695 | AO22: =ROUND(AN22,2)*-1 -> -214695 | AP22: 15751.414 | AQ22: =ROUND(AP22,2)*-1 -> -15751.41
A23: INO1 | B23: 1131100400 | E23: 0 | F23: 9001 | G23: Factory Building | H23: 9001000001 | I23: Buildings & Admin | J23: 1202010202 | L23: Factory Building-18 | O23: 1 | P23: EA | Q23: X | S23: 40147 | T23: 43191 | Y23: 2018 | Z23: 2750000 | AA23: 01 | AB23: ZSLM | AC23: 7921 | AD23: 21 | AE23: 9 | AG23: =_xlfn.CONCAT(AH23," years ",AI23," days") -> 6 years 277 days | AH23: 6 | AI23: 277 | AJ23: 0 | AK23: 0 | AL23: 2750000 | AM23: =ROUND(AL23,2) -> 2750000 | AN23: 856489 | AO23: =ROUND(AN23,2)*-1 -> -856489 | AP23: 62839.368 | AQ23: =ROUND(AP23,2)*-1 -> -62839.37
A24: INO1 | B24: 1131100497 | E24: 0 | F24: 9001 | G24: Factory Building | H24: 9001000001 | I24: Buildings & Admin | J24: 1202010202 | L24: Factory Building-19 | O24: 1 | P24: EA | Q24: X | S24: 40446 | T24: 43191 | Y24: 2018 | Z24: 1875000 | AA24: 01 | AB24: ZSLM | AC24: 8213 | AD24: 22 | AE24: 6 | AG24: =_xlfn.CONCAT(AH24," years ",AI24," days") -> 6 years 277 days | AH24: 6 | AI24: 277 | AJ24: 0 | AK24: 0 | AL24: 1875000 | AM24: =ROUND(AL24,2) -> 1875000 | AN24: 563208 | AO24: =ROUND(AN24,2)*-1 -> -563208 | AP24: 41321.405 | AQ24: =ROUND(AP24,2)*-1 -> -41321.4
... A26: INO1 | B26: 1131101359 | E26: 0 | F26: 9001 | G26: Factory Building | H26: 9001000001 | I26: Buildings & Admin | J26: 1202010202 | L26: Factory Building-21 | O26: 1 | P26: EA | Q26: X | S26: 41716 | T26: 43191 | Y26: 2018 | Z26: 510000 | AA26: 01 | AB26: ZSLM | AC26: 9490 | AD26: 26 | AE26: 0 | AG26: =_xlfn.CONCAT(AH26," years ",AI26," days") -> 6 years 277 days | AH26: 6 | AI26: 277 | AJ26: 0 | AK26: 0 | AL26: 510000 | AM26: =ROUND(AL26,2) -> 510000 | AN26: 132579 | AO26: =ROUND(AN26,2)*-1 -> -132579 | AP26: 9726.5848 | AQ26: =ROUND(AP26,2)*-1 -> -9726.58
A27: INO1 | B27: 1131402939 | E27: 0 | F27: 9001 | G27: Factory Building | H27: 9001000002 | I27: Buildings & Admin | J27: 1202010202 | L27: BEING NON WALKABLE METAL CEILINGCAPITALISED -22 | M27: VIDE PURCHASE FROM ROYAL AIRCON BILL NO 286 DTD | O27: 1 | P27: EA | Q27: X | S27: 43577 | T27: 43577 | Y27: 2019 | Z27: 103395 | AA27: 01 | AB27: ZSLM | AC27: 10950 | AD27: 30 | AE27: 0 | AG27: =_xlfn.CONCAT(AH27," years ",AI27," days") -> 5 years 256 days | AH27: 5 | AI27: 256 | AJ27: 0 | AK27: 0 | AL27: 103395 | AM27: =ROUND(AL27,2) -> 103395 | AN27: 19650 | AO27: =ROUND(AN27,2)*-1 -> -19650 | AP27: 1708.8575 | AQ27: =ROUND(AP27,2)*-1 -> -1708.86
A28: INO1 | B28: 1131403183 | E28: 0 | F28: 9001 | G28: Factory Building | H28: 9001000002 | I28: Buildings & Admin | J28: 1202010202 | L28: Being Non Walkable Metal Ceiling fitting wor-23 | M28: k done | O28: 1 | P28: EA | Q28: X | S28: 43817 | T28: 43817 | Y28: 2019 | Z28: 576753 | AA28: 01 | AB28: ZSLM | AC28: 10950 | AD28: 30 | AE28: 0 | AG28: =_xlfn.CONCAT(AH28," years ",AI28," days") -> 5 years 16 days | AH28: 5 | AI28: 16 | AJ28: 0 | AK28: 0 | AL28: 576753 | AM28: =ROUND(AL28,2) -> 576753 | AN28: 96968 | AO28: =ROUND(AN28,2)*-1 -> -96968 | AP28: 9533.7868 | AQ28: =ROUND(AP28,2)*-1 -> -9533.79
A29: INO1 | B29: 1131403175 | E29: 0 | F29: 9001 | G29: Factory Building | H29: 9001000002 | I29: Buildings & Admin | J29: 1202010202 | L29: Being HR Sheets & HR Plates pur from Gayatri-24 | M29: Steel & Pipes vide inv no 0969 dt 27.11.19 ag P | O29: 1 | P29: EA | Q29: X | S29: 43801 | T29: 43801 | Y29: 2019 | Z29: 200669 | AA29: 01 | AB29: ZSLM | AC29: 10950 | AD29: 30 | AE29: 0 | AG29: =_xlfn.CONCAT(AH29," years ",AI29," days") -> 5 years 32 days | AH29: 5 | AI29: 32 | AJ29: 0 | AK29: 0 | AL29: 200669 | AM29: =ROUND(AL29,2) -> 200669 | AN29: 33143 | AO29: =ROUND(AN29,2)*-1 -> -33143 | AP29: 3317.2282 | AQ29: =ROUND(AP29,2)*-1 -> -3317.23
A30: INO1 | B30: 1131403093 | E30: 0 | F30: 9001 | G30: Factory Building | H30: 9001000003 | I30: Buildings & Admin | J30: 1202010202 | L30: Being Construction work done by Jai Mata Con-25 | M30: struction vide inv no 09 dt 05.11.19 ag PO# SMPO | O30: 1 | P30: EA | Q30: X | S30: 43781 | T30: 43781 | Y30: 2019 | Z30: 733982 | AA30: 01 | AB30: ZSLM | AC30: 10950 | AD30: 30 | AE30: 0 | AG30: =_xlfn.CONCAT(AH30," years ",AI30," days") -> 5 years 52 days | AH30: 5 | AI30: 52 | AJ30: 0 | AK30: 0 | AL30: 733982 | AM30: =ROUND(AL30,2) -> 733982 | AN30: 125816 | AO30: =ROUND(AN30,2)*-1 -> -125816 | AP30: 12132.398 | AQ30: =ROUND(AP30,2)*-1 -> -12132.4
A31: INO1 | B31: 1131403088 | E31: 0 | F31: 9001 | G31: Factory Building | H31: 9001000004 | I31: Buildings & Admin | J31: 1202010202 | L31: Being 3mm Epoxy Flooring work done by H A M -26 | M31: Corporation vide inv no 47 dt 09.11.19 ag PO# SM | O31: 1 | P31: EA | Q31: X | S31: 43771 | T31: 43771 | Y31: 2019 | Z31: 457331 | AA31: 01 | AB31: ZSLM | AC31: 10950 | AD31: 30 | AE31: 0 | AG31: =_xlfn.CONCAT(AH31," years ",AI31," days") -> 5 years 62 days | AH31: 5 | AI31: 62 | AJ31: 0 | AK31: 0 | AL31: 457331 | AM31: =ROUND(AL31,2) -> 457331 | AN31: 78811 | AO31: =ROUND(AN31,2)*-1 -> -78811 | AP31: 7559.8226 | AQ31: =ROUND(AP31,2)*-1 -> -7559.82
A32: INO1 | B32: 1131403188 | E32: 0 | F32: 9001 | G32: Factory Building | H32: 9001000004 | I32: Buildings & Admin | J32: 1202010202 | L32: Being 3mm Epoxy Flooring work done by HAM Co-27 | M32: rporation vide inv no 57 dt 16.12.19 ag PO# SMPO | O32: 1 | P32: EA | Q32: X | S32: 43821 | T32: 43821 | Y32: 2019 | Z32: 111953 | AA32: 01 | AB32: ZSLM | AC32: 10950 | AD32: 30 | AE32: 0 | AG32: =_xlfn.CONCAT(AH32," years ",AI32," days") -> 5 years 12 days | AH32: 5 | AI32: 12 | AJ32: 0 | AK32: 0 | AL32: 111953 | AM32: =ROUND(AL32,2) -> 111953 | AN32: 18782 | AO32: =ROUND(AN32,2)*-1 -> -18782 | AP32: 1850.0689 | AQ32: =ROUND(AP32,2)*-1 -> -1850.07
A33: INO1 | B33: 1131403286 | E33: 0 | F33: 9001 | G33: Factory Building | H33: 9001000005 | I33: Buildings & Admin | J33: 1202010202 | L33: Being New Compound wall work done by Pyramid-28 | M33: Construction vide inv no 3 dt 04.02.20 ag PO# S | O33: 1 | P33: EA | Q33: X | S33: 43931 | T33: 43931 | Y33: 2020 | Z33: 790821 | AA33: 01 | AB33: ZSLM | AC33: 10950 | AD33: 30 | AE33: 0 | AG33: =_xlfn.CONCAT(AH33," years ",AI33," days") -> 4 years 267 days | AH33: 4 | AI33: 267 | AJ33: 0 | AK33: 0 | AL33: 790821 | AM33: =ROUND(AL33,2) -> 790821 | AN33: 124726 | AO33: =ROUND(AN33,2)*-1 -> -124726 | AP33: 13071.851 | AQ33: =ROUND(AP33,2)*-1 -> -13071.85
A34: INO1 | B34: 1131403288 | E34: 0 | F34: 9001 | G34: Factory Building | H34: 9001000006 | I34: Buildings & Admin | J34: 1202010202 | L34: Being MS Round & Square Bar pur from Sainath-29 | M34: Structures Pvt Ltd vide inv no GST3983 dt 08.01 | O34: 1 | P34: EA | Q34: X | S34: 43931 | T34: 43931 | Y34: 2020 | Z34: 32667 | AA34: 01 | AB34: ZSLM | AC34: 10950 | AD34: 30 | AE34: 0 | AG34: =_xlfn.CONCAT(AH34," years ",AI34," days") -> 4 years 267 days | AH34: 4 | AI34: 267 | AJ34: 0 | AK34: 0 | AL34: 32667 | AM34: =ROUND(AL34,2) -> 32667 | AN34: 5152 | AO34: =ROUND(AN34,2)*-1 -> -5152 | AP34: 540.11288 | AQ34: =ROUND(AP34,2)*-1 -> -540.11
A35: INO1 | B35: 1131403289 | E35: 0 | F35: 9001 | G35: Factory Building | H35: 9001000006 | I35: Buildings & Admin | J35: 1202010202 | L35: Being Main Gate Office Side Old Road RCC Ruf-30 | M35: f work done by Jai Mata Construction vide inv no | O35: 1 | P35: EA | Q35: X | S35: 43931 | T35: 43931 | Y35: 2020 | Z35: 216737 | AA35: 01 | AB35: ZSLM | AC35: 10950 | AD35: 30 | AE35: 0 | AG35: =_xlfn.CONCAT(AH35," years ",AI35," days") -> 4 years 267 days | AH35: 4 | AI35: 267 | AJ35: 0 | AK35: 0 | AL35: 216737 | AM35: =ROUND(AL35,2) -> 216737 | AN35: 34183 | AO35: =ROUND(AN35,2)*-1 -> -34183 | AP35: 3582.68 | AQ35: =ROUND(AP35,2)*-1 -> -3582.68
A36: INO1 | B36: 1131403491 | E36: 0 | F36: 9001 | G36: Factory Building | H36: 9001000007 | I36: Buildings & Admin | J36: 1202010202 | L36: Being MS Chanel, Chakar Plate, MS angle, MS -31 | M36: Pipes pur from Sainath Structures Pvt Ltd vide i | O36: 1 | P36: EA | Q36: X | S36: 44183 | T36: 44183 | Y36: 2020 | Z36: 67468 | AA36: 01 | AB36: ZSLM | AC36: 10950 | AD36: 30 | AE36: 0 | AG36: =_xlfn.CONCAT(AH36," years ",AI36," days") -> 4 years 15 days | AH36: 4 | AI36: 15 | AJ36: 0 | AK36: 0 | AL36: 67468 | AM36: =ROUND(AL36,2) -> 67468 | AN36: 9088 | AO36: =ROUND(AN36,2)*-1 -> -9088 | AP36: 1115.3797 | AQ36: =ROUND(AP36,2)*-1 -> -1115.38
A37: INO1 | B37: 1131403492 | E37: 0 | F37: 9001 | G37: Factory Building | H37: 9001000007 | I37: Buildings & Admin | J37: 1202010202 | L37: Being Fabrication Work for Extra Receiver In-32 | M37: stallation for Header Connecting With Support Wo | O37: 1 | P37: EA | Q37: X | S37: 44185 | T37: 44185 | Y37: 2020 | Z37: 19636 | AA37: 01 | AB37: ZSLM | AC37: 10950 | AD37: 30 | AE37: 0 | AG37: =_xlfn.CONCAT(AH37," years ",AI37," days") -> 4 years 13 days | AH37: 4 | AI37: 13 | AJ37: 0 | AK37: 0 | AL37: 19636 | AM37: =ROUND(AL37,2) -> 19636 | AN37: 2641 | AO37: =ROUND(AN37,2)*-1 -> -2641 | AP37: 325.02228 | AQ37: =ROUND(AP37,2)*-1 -> -325.02
A38: INO1 | B38: 1131403486 | E38: 0 | F38: 9001 | G38: Factory Building | H38: 9001000007 | I38: Buildings & Admin | J38: 1202010202 | L38: Being PARKING SHADE FABRICATION WORK DONE FO-33 | M38: R NEW PLANT pur from Grace Engineering Works vid | O38: 1 | P38: EA | Q38: X | S38: 44177 | T38: 44177 | Y38: 2020 | Z38: 31242 | AA38: 01 | AB38: ZSLM | AC38: 10950 | AD38: 30 | AE38: 0 | AG38: =_xlfn.CONCAT(AH38," years ",AI38," days") -> 4 years 21 days | AH38: 4 | AI38: 21 | AJ38: 0 | AK38: 0 | AL38: 31242 | AM38: =ROUND(AL38,2) -> 31242 | AN38: 4226 | AO38: =ROUND(AN38,2)*-1 -> -4226 | AP38: 515.93644 | AQ38: =ROUND(AP38,2)*-1 -> -515.94
... A53: INO1 | B53: 1131404646 | E53: 0 | F53: 9001 | G53: Factory Building | H53: 9001000016 | I53: Buildings & Admin | J53: 1202010202 | L53: Addition to New Building (Addition to New Pl-48 | M53: ant) | O53: 1 | P53: EA | Q53: X | S53: 44986 | T53: 44986 | Y53: 2023 | Z53: 1.5146637e+08 | AA53: 01 | AB53: ZSLM | AC53: 10950 | AD53: 30 | AE53: 0 | AG53: =_xlfn.CONCAT(AH53," years ",AI53," days") -> 1 years 307 days | AH53: 1 | AI53: 307 | AJ53: 0 | AK53: 0 | AL53: 1.5146637e+08 | AM53: =ROUND(AL53,2) -> 1.5146637e+08 | AN53: 9295470 | AO53: =ROUND(AN53,2)*-1 -> -9295470 | AP53: 2503690.7 | AQ53: =ROUND(AP53,2)*-1 -> -2503690.7
A54: INO1 | B54: 1131404732 | E54: 0 | F54: 9001 | G54: Factory Building | H54: 9001000017 | I54: Buildings & Admin | J54: 1202010202 | L54: Improvement In Factory Building-49 | O54: 1 | P54: EA | Q54: X | S54: 45047 | T54: 45047 | Y54: 2023 | Z54: 3552291.3 | AA54: 01 | AB54: ZSLM | AC54: 10950 | AD54: 30 | AE54: 0 | AG54: =_xlfn.CONCAT(AH54," years ",AI54," days") -> 1 years 246 days | AH54: 1 | AI54: 246 | AJ54: 0 | AK54: 0 | AL54: 3552291.3 | AM54: =ROUND(AL54,2) -> 3552291.3 | AN54: 198215 | AO54: =ROUND(AN54,2)*-1 -> -198215 | AP54: 58717.85 | AQ54: =ROUND(AP54,2)*-1 -> -58717.85
A55: INO1 | B55: 1131404801 | E55: 0 | F55: 9001 | G55: Factory Building | H55: 9001000017 | I55: Buildings & Admin | J55: 1202010202 | L55: B/NO. 033 DT: 15.06.23 OF GRACE ENGINEERING -50 | M55: WORKS BOOKED FOR STP PLANT ROOF MAKING , JALLY | O55: 1 | P55: EA | Q55: X | S55: 45108 | T55: 45108 | Y55: 2023 | Z55: 47780 | AA55: 01 | AB55: ZSLM | AC55: 10950 | AD55: 30 | AE55: 0 | AG55: =_xlfn.CONCAT(AH55," years ",AI55," days") -> 1 years 185 days | AH55: 1 | AI55: 185 | AJ55: 0 | AK55: 0 | AL55: 47780 | AM55: =ROUND(AL55,2) -> 47780 | AN55: 2400 | AO55: =ROUND(AN55,2)*-1 -> -2400 | AP55: 789.6968 | AQ55: =ROUND(AP55,2)*-1 -> -789.7
A56: INO1 | B56: 1131404809 | E56: 0 | F56: 9001 | G56: Factory Building | H56: 9001000017 | I56: Buildings & Admin | J56: 1202010202 | L56: B/NO. 43 DT: 03.07.23 OF PRAFULLA SHEET BOOK-51 | M56: ED FOR PVC PIPE RAIN WATER LINE FITTING , ELBOW | O56: 1 | P56: EA | Q56: X | S56: 45111 | T56: 45111 | Y56: 2023 | Z56: 34522 | AA56: 01 | AB56: ZSLM | AC56: 10950 | AD56: 30 | AE56: 0 | AG56: =_xlfn.CONCAT(AH56," years ",AI56," days") -> 1 years 182 days | AH56: 1 | AI56: 182 | AJ56: 0 | AK56: 0 | AL56: 34522 | AM56: =ROUND(AL56,2) -> 34522 | AN56: 1725 | AO56: =ROUND(AN56,2)*-1 -> -1725 | AP56: 570.16128 | AQ56: =ROUND(AP56,2)*-1 -> -570.16
A57: INO1 | B57: 1131404920 | E57: 0 | F57: 9001 | G57: Factory Building | H57: 9001000018 | I57: Buildings & Admin | J57: 1202010202 | L57: Being Factory Building work Capitalised-52 | O57: 1 | P57: EA | Q57: X | S57: 45199 | T57: 45199 | Y57: 2023 | Z57: 9299379.8 | AA57: 01 | AB57: ZSLM | AC57: 10950 | AD57: 30 | AE57: 0 | AG57: =_xlfn.CONCAT(AH57," years ",AI57," days") -> 1 years 94 days | AH57: 1 | AI57: 94 | AJ57: 0 | AK57: 0 | AL57: 9299379.8 | AM57: =ROUND(AL57,2) -> 9299379.8 | AN57: 389810 | AO57: =ROUND(AN57,2)*-1 -> -389810 | AP57: 153715.39 | AQ57: =ROUND(AP57,2)*-1 -> -153715.39
...

Sheet SOM
A1: Company Code | B1: External/Legacy Asset Number* External/legacy asset ID. It is an unique number that identifies a fixed asset in the Legacy System. Please note: In S/4HANA Cloud only INTERNAL number assignment is supported. The legacy asset number is migrated to the field "Original Asset" in the tab "Origin" for reference. Key fields are mandatory and must always be filled with a unique key. If there is internal numbering, you can provide the key of your source system or any other unique key. The key is technically mandatory for the tool to internally connect the records of subordinated sheets with the records of the superordinated sheets. Type: Text Length: 12 | C1: Asset number | D1: Main Asset Legacy Number | E1: Asset Subnumber* Must be "0", when migrating a MAIN asset source file. Must be a sequential number (unequal "0"), when migrating an asset subnumber source file (max. 4-digits). The asset subnumber is migrated to the field "Original Asset Subnumber" in the tab "Origin" for reference. This is the number which, together with the main asset number, uniquely identifies a fixed asset in Asset Accounting. Using the asset sub-number, you can: - Provide for separate management of later acquisitions to assets. - Represent complex fixed assets with their component parts. Type: Text Length: 4 | F1: Asset Class in SAP | G1: Asset Class in SAP | I1: PM Sheet Maped Cost Center | J1: Cost Center Code | K1: Equipment ID | L1: Asset Description* Asset Description Type: Text Length: 50 | M1: Asset Description 2 Additional Asset description. Type: Text Length: 50 | N1: Serial Number You can enter the manufacturer's serial number in this field. Type: Text Length: 18 | O1: Quantity Quantity Type: Number Length: 13 Decimal: 3 | P1: Base Unit of Measure Base Unit of Measure, for example: KG, KM, TON... Type: Text Length: 80 | Q1: Asset is managed historically Set this indicator to 'X', if the asset is managed historically. Type: Text Length: 1 | R1: Asset Main Number Text In this field, you can enter any desired name for an asset main number. The text is then used, for example, in reporting, and in the display values transaction when accessing totals per asset main number. Type: Text Length: 50 | S1: Original Purchase Date | T1: Asset Capitalization Date* Reference date of the posting that leads to asset being capitalized. Type: Date | U1: Deactivation Date Asset value date of the retirement posting for a full retirement in this field. Type: Date | V1: Plant The Plant is mandatory for migrating an Asset Location. Without indicating the Plant the Asset Location cannot be determined. Type: Text Length: 80 | W1: Asset Location Migrating an Asset Location, the indication of the Plant is mandatory. Without a plant the Asset Location cannot be determined. Type: Text Length: 80 | X1: License Plate No. of Vehicle You can enter the license plate number for a vehicle here. Your entry is saved as time-dependent data, so that a history is created when there is a change in the license plate number. Type: Text Length: 15 | Y1: Fiscal Year of Original Acquisition Fiscal year in which the asset was originally acquired (before the asset transfer). This field is not automatically filled; you need to supply it. Type: Number Length: 4 | Z1: Original Acquisition Value Acquisition value of the asset before the asset transfer. This field is not automatically filled; you need to supply it. Type: Number Length: 23 Decimal: 2 | AA1: Depreciation Area* Depreciation area, which is managed in the system as a real depreciation area (not a derived depreciation area). Type: Text Length: 80 | AB1: Depreciation Key* Depreciation keys are defined at the level of the chart of depreciation. Type: Text Length: 80 | AC1: Life of Assets as per Co's Act | AD1: Useful Life (in years) The two fields ‘Useful Life (in years)’ and ‘Useful Life (in periods)’ are additive. For example, a useful life of 3.5 years would be maintained as ‘Useful Life (in years)’ = 3 and ‘Useful Life (in periods)’ = 6. Type: Number Length: 3 | AE1: Useful Life (in periods) The two fields ‘Useful Life (in years)’ and ‘Useful Life (in periods)’ are additive. For example, a useful life of 3.5 years would be maintained as ‘Useful Life (in years)’ = 3 and ‘Useful Life (in periods)’ = 6. Type: Number Length: 3 | AF1: Used life | AG1: Exp. usef. life in years at start of FY The portion of the useful life of the asset that has already expired. Type: Number Length: 3 | AH1: Exp. usef. life in perio. at start of FY The portion of the useful life of the asset that has already expired. Type: Number Length: 3 | AI1: Cumulated Acquisition Value Please enter one row for each depreciation area. Type: Number Length: 23 Decimal: 2 | AJ1: Accumulated Ordinary Depreciation Must be negative, e.g. -1267,00, in most of the business cases. Type: Number Length: 23 Decimal: 2 | AK1: Current Fiscal Year* Current fiscal year = active fiscal year in system. Period, 12 as a rule, for which the company is to create its inventory and balance sheet. The fiscal year can be the same as the calendar year, but does not have to be. Type: Number Length: 4 | AL1: Posted Ordinary Deprec. for the Year Depreciation values must be negative, e.g. -1234,56 and corrections of depreciation values positve, e.g. 1234,56. Type: Number Length: 23 Decimal: 2
A2: IN01 | B2: 1131100078 | E2: 0 | F2: Factory Building | G2: 9001 | H2: 9001000001 | I2: Buildings & Admin | J2: 1202010202 | L2: Factory Building-8 | O2: 1 | P2: EA | Q2: X | S2: 38078 | T2: 43340 | Y2: 2018 | Z2: 22874756 | AA2: 01 | AB2: ZSLM | AC2: 5694 | AD2: 15 | AE2: 7 | AF2: =_xlfn.CONCAT(AG2," years ",AH2," days") -> 6 years 128 days | AG2: 6 | AH2: 128 | AI2: 22874756 | AJ2: 9308186 | AK2: 2025 | AL2: 727138.98
A3: IN01 | B3: 1131100083 | E3: 0 | F3: Factory Building | G3: 9001 | H3: 9001000001 | I3: Buildings & Admin | J3: 1202010202 | L3: Factory Building-9 | O3: 1 | P3: EA | Q3: X | S3: 38107 | T3: 43340 | Y3: 2018 | Z3: 131423.56 | AA3: 01 | AB3: ZSLM | AC3: 5731 | AD3: 15 | AE3: 9 | AF3: =_xlfn.CONCAT(AG3," years ",AH3," days") -> 6 years 128 days | AG3: 6 | AH3: 128 | AI3: 131423.56 | AJ3: 53134 | AK3: 2025 | AL3: 4150.3813
A4: IN01 | B4: 1131100087 | E4: 0 | F4: Factory Building | G4: 9001 | H4: 9001000001 | I4: Buildings & Admin | J4: 1202010202 | L4: Factory Building-10 | O4: 1 | P4: EA | Q4: X | S4: 38138 | T4: 43340 | Y4: 2018 | Z4: 385260.71 | AA4: 01 | AB4: ZSLM | AC4: 5767 | AD4: 15 | AE4: 10 | AF4: =_xlfn.CONCAT(AG4," years ",AH4," days") -> 6 years 128 days | AG4: 6 | AH4: 128 | AI4: 385260.71 | AJ4: 154786 | AK4: 2025 | AL4: 12091.36
A5: IN01 | B5: 1131100092 | E5: 0 | F5: Factory Building | G5: 9001 | H5: 9001000001 | I5: Buildings & Admin | J5: 1202010202 | L5: Factory Building-11 | O5: 1 | P5: EA | Q5: X | S5: 38168 | T5: 43340 | Y5: 2018 | Z5: 104811.22 | AA5: 01 | AB5: ZSLM | AC5: 5767 | AD5: 15 | AE5: 10 | AF5: =_xlfn.CONCAT(AG5," years ",AH5," days") -> 6 years 128 days | AG5: 6 | AH5: 128 | AI5: 104811.22 | AJ5: 42110 | AK5: 2025 | AL5: 3289.3506
A6: IN01 | B6: 1131100094 | E6: 0 | F6: Factory Building | G6: 9001 | H6: 9001000001 | I6: Buildings & Admin | J6: 1202010202 | L6: Factory Building-12 | O6: 1 | P6: EA | Q6: X | S6: 38220 | T6: 43340 | Y6: 2018 | Z6: 525906 | AA6: 01 | AB6: ZSLM | AC6: 5840 | AD6: 16 | AE6: 0 | AF6: =_xlfn.CONCAT(AG6," years ",AH6," days") -> 6 years 128 days | AG6: 6 | AH6: 128 | AI6: 525906 | AJ6: 208651 | AK6: 2025 | AL6: 16299.888
A7: IN01 | B7: 1131100100 | E7: 0 | F7: Factory Building | G7: 9001 | H7: 9001000001 | I7: Buildings & Admin | J7: 1202010202 | L7: Factory Building-13 | O7: 1 | P7: EA | Q7: X | S7: 38260 | T7: 43340 | Y7: 2018 | Z7: 522189.82 | AA7: 01 | AB7: ZSLM | AC7: 5877 | AD7: 16 | AE7: 1 | AF7: =_xlfn.CONCAT(AG7," years ",AH7," days") -> 6 years 128 days | AG7: 6 | AH7: 128 | AI7: 522189.82 | AJ7: 205873 | AK7: 2025 | AL7: 16082.16
A8: IN01 | B8: 1131100110 | E8: 0 | F8: Factory Building | G8: 9001 | H8: 9001000001 | I8: Buildings & Admin | J8: 1202010202 | L8: Factory Building-14 | O8: 1 | P8: EA | Q8: X | S8: 38352 | T8: 43340 | Y8: 2018 | Z8: 161919.78 | AA8: 01 | AB8: ZSLM | AC8: 5950 | AD8: 16 | AE8: 4 | AF8: =_xlfn.CONCAT(AG8," years ",AH8," days") -> 6 years 128 days | AG8: 6 | AH8: 128 | AI8: 161919.78 | AJ8: 63054 | AK8: 2025 | AL8: 4925.1562
A9: IN01 | B9: 1131100116 | E9: 0 | F9: Factory Building | G9: 9001 | H9: 9001000001 | I9: Buildings & Admin | J9: 1202010202 | L9: Factory Building-15 | O9: 1 | P9: EA | Q9: X | S9: 38383 | T9: 43340 | Y9: 2018 | Z9: 114680.74 | AA9: 01 | AB9: ZSLM | AC9: 5986 | AD9: 16 | AE9: 5 | AF9: =_xlfn.CONCAT(AG9," years ",AH9," days") -> 6 years 128 days | AG9: 6 | AH9: 128 | AI9: 114680.74 | AJ9: 44390 | AK9: 2025 | AL9: 3467.1538
A10: IN01 | B10: 1131100119 | E10: 0 | F10: Factory Building | G10: 9001 | H10: 9001000001 | I10: Buildings & Admin | J10: 1202010202 | L10: Factory Building-16 | O10: 1 | P10: EA | Q10: X | S10: 38411 | T10: 43340 | Y10: 2018 | Z10: 632764.31 | AA10: 01 | AB10: ZSLM | AC10: 6023 | AD10: 16 | AE10: 6 | AF10: =_xlfn.CONCAT(AG10," years ",AH10," days") -> 6 years 128 days | AG10: 6 | AH10: 128 | AI10: 632764.31 | AJ10: 243419 | AK10: 2025 | AL10: 19015.788
A11: IN01 | B11: 1131100122 | E11: 0 | F11: Factory Building | G11: 9001 | H11: 9001000001 | I11: Buildings & Admin | J11: 1202010202 | L11: Factory Building-17 | O11: 1 | P11: EA | Q11: X | S11: 38442 | T11: 43340 | Y11: 2018 | Z11: 536344.26 | AA11: 01 | AB11: ZSLM | AC11: 6059 | AD11: 16 | AE11: 7 | AF11: =_xlfn.CONCAT(AG11," years ",AH11," days") -> 6 years 128 days | AG11: 6 | AH11: 128 | AI11: 536344.26 | AJ11: 205101 | AK11: 2025 | AL11: 16022.54
A12: IN01 | B12: 1131100400 | E12: 0 | F12: Factory Building | G12: 9001 | H12: 9001000001 | I12: Buildings & Admin | J12: 1202010202 | L12: Factory Building-18 | O12: 1 | P12: EA | Q12: X | S12: 40147 | T12: 43340 | Y12: 2018 | Z12: 2765865.1 | AA12: 01 | AB12: ZSLM | AC12: 7775 | AD12: 21 | AE12: 4 | AF12: =_xlfn.CONCAT(AG12," years ",AH12," days") -> 6 years 128 days | AG12: 6 | AH12: 128 | AI12: 2765865.1 | AJ12: 824246 | AK12: 2025 | AL12: 64388.19
A13: IN01 | B13: 1131100497 | E13: 0 | F13: Factory Building | G13: 9001 | H13: 9001000001 | I13: Buildings & Admin | J13: 1202010202 | L13: Factory Building-19 | O13: 1 | P13: EA | Q13: X | S13: 40446 | T13: 43340 | Y13: 2018 | Z13: 1886825.9 | AA13: 01 | AB13: ZSLM | AC13: 8067 | AD13: 22 | AE13: 1 | AF13: =_xlfn.CONCAT(AG13," years ",AH13," days") -> 6 years 128 days | AG13: 6 | AH13: 128 | AI13: 1886825.9 | AJ13: 541933 | AK13: 2025 | AL13: 42335.16
... A21: IN01 | B21: 1131400975 | E21: 0 | F21: Factory Building | G21: 9001 | H21: 9001000001 | I21: Buildings & Admin | J21: 1202010202 | L21: Factory Building-6 | O21: 1 | P21: EA | Q21: X | S21: 41364 | T21: 43340 | Y21: 2018 | Z21: 16675000 | AA21: 01 | AB21: ZSLM | AC21: 8979 | AD21: 24 | AE21: 7 | AF21: =_xlfn.CONCAT(AG21," years ",AH21," days") -> 6 years 128 days | AG21: 6 | AH21: 128 | AI21: 16675000 | AJ21: 4302926 | AK21: 2025 | AL21: 336137.37
A22: IN01 | B22: 1131401678 | E22: 0 | F22: Factory Building | G22: 9001 | H22: 9001000001 | I22: Buildings & Admin | J22: 1202010202 | L22: Toilet Line Orrisa Pan Fitting with Pipe Lin-7 | M22: e Complete | O22: 4 | P22: EA | Q22: X | S22: 42217 | T22: 43340 | Y22: 2018 | Z22: 55000 | AA22: 01 | AB22: ZSLM | AC22: 9819 | AD22: 26 | AE22: 11 | AF22: =_xlfn.CONCAT(AG22," years ",AH22," days") -> 6 years 128 days | AG22: 6 | AH22: 128 | AI22: 55000 | AJ22: 12978 | AK22: 2025 | AL22: 1014.2599
A23: IN01 | B23: 1131402939 | E23: 0 | F23: Factory Building | G23: 9001 | H23: 9001000002 | I23: Buildings & Admin | J23: 1202010202 | L23: BEING NON WALKABLE METAL CEILINGCAPITALISED -22 | M23: VIDE PURCHASE FROM ROYAL AIRCON BILL NO 286 DTD | O23: 1 | P23: EA | Q23: X | S23: 43577 | T23: 43577 | Y23: 2019 | Z23: 103395 | AA23: 01 | AB23: ZSLM | AC23: 10950 | AD23: 30 | AE23: 0 | AF23: =_xlfn.CONCAT(AG23," years ",AH23," days") -> 5 years 256 days | AG23: 5 | AH23: 256 | AI23: 103395 | AJ23: 19650 | AK23: 2025 | AL23: 1708.8575
A24: IN01 | B24: 1131403183 | E24: 0 | F24: Factory Building | G24: 9001 | H24: 9001000002 | I24: Buildings & Admin | J24: 1202010202 | L24: Being Non Walkable Metal Ceiling fitting wor-23 | M24: k done | O24: 1 | P24: EA | Q24: X | S24: 43817 | T24: 43817 | Y24: 2019 | Z24: 576753 | AA24: 01 | AB24: ZSLM | AC24: 10950 | AD24: 30 | AE24: 0 | AF24: =_xlfn.CONCAT(AG24," years ",AH24," days") -> 5 years 16 days | AG24: 5 | AH24: 16 | AI24: 576753 | AJ24: 96968 | AK24: 2025 | AL24: 9533.7868
A25: IN01 | B25: 1131403175 | E25: 0 | F25: Factory Building | G25: 9001 | H25: 9001000002 | I25: Buildings & Admin | J25: 1202010202 | L25: Being HR Sheets & HR Plates pur from Gayatri-24 | M25: Steel & Pipes vide inv no 0969 dt 27.11.19 ag P | O25: 1 | P25: EA | Q25: X | S25: 43801 | T25: 43801 | Y25: 2019 | Z25: 200669 | AA25: 01 | AB25: ZSLM | AC25: 10950 | AD25: 30 | AE25: 0 | AF25: =_xlfn.CONCAT(AG25," years ",AH25," days") -> 5 years 32 days | AG25: 5 | AH25: 32 | AI25: 200669 | AJ25: 33143 | AK25: 2025 | AL25: 3317.2282
A26: IN01 | B26: 1131403093 | E26: 0 | F26: Factory Building | G26: 9001 | H26: 9001000003 | I26: Buildings & Admin | J26: 1202010202 | L26: Being Construction work done by Jai Mata Con-25 | M26: struction vide inv no 09 dt 05.11.19 ag PO# SMPO | O26: 1 | P26: EA | Q26: X | S26: 43781 | T26: 43781 | Y26: 2019 | Z26: 733982 | AA26: 01 | AB26: ZSLM | AC26: 10950 | AD26: 30 | AE26: 0 | AF26: =_xlfn.CONCAT(AG26," years ",AH26," days") -> 5 years 52 days | AG26: 5 | AH26: 52 | AI26: 733982 | AJ26: 125816 | AK26: 2025 | AL26: 12132.398
A27: IN01 | B27: 1131403088 | E27: 0 | F27: Factory Building | G27: 9001 | H27: 9001000004 | I27: Buildings & Admin | J27: 1202010202 | L27: Being 3mm Epoxy Flooring work done by H A M -26 | M27: Corporation vide inv no 47 dt 09.11.19 ag PO# SM | O27: 1 | P27: EA | Q27: X | S27: 43771 | T27: 43771 | Y27: 2019 | Z27: 457331 | AA27: 01 | AB27: ZSLM | AC27: 10950 | AD27: 30 | AE27: 0 | AF27: =_xlfn.CONCAT(AG27," years ",AH27," days") -> 5 years 62 days | AG27: 5 | AH27: 62 | AI27: 457331 | AJ27: 78811 | AK27: 2025 | AL27: 7559.8226
A28: IN01 | B28: 1131403188 | E28: 0 | F28: Factory Building | G28: 9001 | H28: 9001000004 | I28: Buildings & Admin | J28: 1202010202 | L28: Being 3mm Epoxy Flooring work done by HAM Co-27 | M28: rporation vide inv no 57 dt 16.12.19 ag PO# SMPO | O28: 1 | P28: EA | Q28: X | S28: 43821 | T28: 43821 | Y28: 2019 | Z28: 111953 | AA28: 01 | AB28: ZSLM | AC28: 10950 | AD28: 30 | AE28: 0 | AF28: =_xlfn.CONCAT(AG28," years ",AH28," days") -> 5 years 12 days | AG28: 5 | AH28: 12 | AI28: 111953 | AJ28: 18782 | AK28: 2025 | AL28: 1850.0689
A29: IN01 | B29: 1131403286 | E29: 0 | F29: Factory Building | G29: 9001 | H29: 9001000005 | I29: Buildings & Admin | J29: 1202010202 | L29: Being New Compound wall work done by Pyramid-28 | M29: Construction vide inv no 3 dt 04.02.20 ag PO# S | O29: 1 | P29: EA | Q29: X | S29: 43931 | T29: 43931 | Y29: 2020 | Z29: 790821 | AA29: 01 | AB29: ZSLM | AC29: 10950 | AD29: 30 | AE29: 0 | AF29: =_xlfn.CONCAT(AG29," years ",AH29," days") -> 4 years 267 days | AG29: 4 | AH29: 267 | AI29: 790821 | AJ29: 124726 | AK29: 2025 | AL29: 13071.851
A30: IN01 | B30: 1131403288 | E30: 0 | F30: Factory Building | G30: 9001 | H30: 9001000006 | I30: Buildings & Admin | J30: 1202010202 | L30: Being MS Round & Square Bar pur from Sainath-29 | M30: Structures Pvt Ltd vide inv no GST3983 dt 08.01 | O30: 1 | P30: EA | Q30: X | S30: 43931 | T30: 43931 | Y30: 2020 | Z30: 32667 | AA30: 01 | AB30: ZSLM | AC30: 10950 | AD30: 30 | AE30: 0 | AF30: =_xlfn.CONCAT(AG30," years ",AH30," days") -> 4 years 267 days | AG30: 4 | AH30: 267 | AI30: 32667 | AJ30: 5152 | AK30: 2025 | AL30: 540.11288
A31: IN01 | B31: 1131403289 | E31: 0 | F31: Factory Building | G31: 9001 | H31: 9001000006 | I31: Buildings & Admin | J31: 1202010202 | L31: Being Main Gate Office Side Old Road RCC Ruf-30 | M31: f work done by Jai Mata Construction vide inv no | O31: 1 | P31: EA | Q31: X | S31: 43931 | T31: 43931 | Y31: 2020 | Z31: 216737 | AA31: 01 | AB31: ZSLM | AC31: 10950 | AD31: 30 | AE31: 0 | AF31: =_xlfn.CONCAT(AG31," years ",AH31," days") -> 4 years 267 days | AG31: 4 | AH31: 267 | AI31: 216737 | AJ31: 34183 | AK31: 2025 | AL31: 3582.68
A32: IN01 | B32: 1131403491 | E32: 0 | F32: Factory Building | G32: 9001 | H32: 9001000007 | I32: Buildings & Admin | J32: 1202010202 | L32: Being MS Chanel, Chakar Plate, MS angle, MS -31 | M32: Pipes pur from Sainath Structures Pvt Ltd vide i | O32: 1 | P32: EA | Q32: X | S32: 44183 | T32: 44183 | Y32: 2020 | Z32: 67468 | AA32: 01 | AB32: ZSLM | AC32: 10950 | AD32: 30 | AE32: 0 | AF32: =_xlfn.CONCAT(AG32," years ",AH32," days") -> 4 years 15 days | AG32: 4 | AH32: 15 | AI32: 67468 | AJ32: 9088 | AK32: 2025 | AL32: 1115.3797
A33: IN01 | B33: 1131403492 | E33: 0 | F33: Factory Building | G33: 9001 | H33: 9001000007 | I33: Buildings & Admin | J33: 1202010202 | L33: Being Fabrication Work for Extra Receiver In-32 | M33: stallation for Header Connecting With Support Wo | O33: 1 | P33: EA | Q33: X | S33: 44185 | T33: 44185 | Y33: 2020 | Z33: 19636 | AA33: 01 | AB33: ZSLM | AC33: 10950 | AD33: 30 | AE33: 0 | AF33: =_xlfn.CONCAT(AG33," years ",AH33," days") -> 4 years 13 days | AG33: 4 | AH33: 13 | AI33: 19636 | AJ33: 2641 | AK33: 2025 | AL33: 325.02228
... A49: IN01 | B49: 1131404646 | E49: 0 | F49: Factory Building | G49: 9001 | H49: 9001000016 | I49: Buildings & Admin | J49: 1202010202 | L49: Addition to New Building (Addition to New Pl-48 | M49: ant) | O49: 1 | P49: EA | Q49: X | S49: 44986 | T49: 44986 | Y49: 2023 | Z49: 1.5146637e+08 | AA49: 01 | AB49: ZSLM | AC49: 10950 | AD49: 30 | AE49: 0 | AF49: =_xlfn.CONCAT(AG49," years ",AH49," days") -> 1 years 307 days | AG49: 1 | AH49: 307 | AI49: 1.5146637e+08 | AJ49: 9295470 | AK49: 2025 | AL49: 2503690.7
A50: IN01 | B50: 1131404732 | E50: 0 | F50: Factory Building | G50: 9001 | H50: 9001000017 | I50: Buildings & Admin | J50: 1202010202 | L50: Improvement In Factory Building-49 | O50: 1 | P50: EA | Q50: X | S50: 45047 | T50: 45047 | Y50: 2023 | Z50: 3552291.3 | AA50: 01 | AB50: ZSLM | AC50: 10950 | AD50: 30 | AE50: 0 | AF50: =_xlfn.CONCAT(AG50," years ",AH50," days") -> 1 years 246 days | AG50: 1 | AH50: 246 | AI50: 3552291.3 | AJ50: 198215 | AK50: 2025 | AL50: 58717.85
A51: IN01 | B51: 1131404801 | E51: 0 | F51: Factory Building | G51: 9001 | H51: 9001000017 | I51: Buildings & Admin | J51: 1202010202 | L51: B/NO. 033 DT: 15.06.23 OF GRACE ENGINEERING -50 | M51: WORKS BOOKED FOR STP PLANT ROOF MAKING , JALLY | O51: 1 | P51: EA | Q51: X | S51: 45108 | T51: 45108 | Y51: 2023 | Z51: 47780 | AA51: 01 | AB51: ZSLM | AC51: 10950 | AD51: 30 | AE51: 0 | AF51: =_xlfn.CONCAT(AG51," years ",AH51," days") -> 1 years 185 days | AG51: 1 | AH51: 185 | AI51: 47780 | AJ51: 2400 | AK51: 2025 | AL51: 789.6968
A52: IN01 | B52: 1131404809 | E52: 0 | F52: Factory Building | G52: 9001 | H52: 9001000017 | I52: Buildings & Admin | J52: 1202010202 | L52: B/NO. 43 DT: 03.07.23 OF PRAFULLA SHEET BOOK-51 | M52: ED FOR PVC PIPE RAIN WATER LINE FITTING , ELBOW | O52: 1 | P52: EA | Q52: X | S52: 45111 | T52: 45111 | Y52: 2023 | Z52: 34522 | AA52: 01 | AB52: ZSLM | AC52: 10950 | AD52: 30 | AE52: 0 | AF52: =_xlfn.CONCAT(AG52," years ",AH52," days") -> 1 years 182 days | AG52: 1 | AH52: 182 | AI52: 34522 | AJ52: 1725 | AK52: 2025 | AL52: 570.16128
A53: IN01 | B53: 1131404920 | E53: 0 | F53: Factory Building | G53: 9001 | H53: 9001000018 | I53: Buildings & Admin | J53: 1202010202 | L53: Being Factory Building work Capitalised-52 | O53: 1 | P53: EA | Q53: X | S53: 45199 | T53: 45199 | Y53: 2023 | Z53: 9299379.8 | AA53: 01 | AB53: ZSLM | AC53: 10950 | AD53: 30 | AE53: 0 | AF53: =_xlfn.CONCAT(AG53," years ",AH53," days") -> 1 years 94 days | AG53: 1 | AH53: 94 | AI53: 9299379.8 | AJ53: 389810 | AK53: 2025 | AL53: 153715.39
A54: IN01 | B54: 1131404966 | E54: 0 | F54: Factory Building | G54: 9001 | H54: 9001000019 | I54: Buildings & Admin | J54: 1202010202 | L54: B/NO. 27 DT: 23.05.23 OF PANCHAL INDUSTRIES -53 | M54: BOOKED FOR PUR ROLLING SHUTTER VIDE TSGO/23-24/ | O54: 10 | P54: EA | Q54: X | S54: 45231 | T54: 45231 | Y54: 2023 | Z54: 474388 | AA54: 01 | AB54: ZSLM | AC54: 10950 | AD54: 30 | AE54: 0 | AF54: =_xlfn.CONCAT(AG54," years ",AH54," days") -> 1 years 62 days | AG54: 1 | AH54: 62 | AI54: 474388 | AJ54: 18499 | AK54: 2025 | AL54: 7841.4479
A55: IN01 | B55: 1131404967 | E55: 0 | F55: Factory Building | G55: 9001 | H55: 9001000019 | I55: Buildings & Admin | J55: 1202010202 | L55: B/NO. 88 DT: 04.08.23 OF PANCHAL INDUSTRIES -54 | M55: BOOKED FOR PUR GLASS DOOR , RADAR & DIGITAL LOC | O55: 47 | P55: EA | Q55: X | S55: 45231 | T55: 45231 | Y55: 2023 | Z55: 153400 | AA55: 01 | AB55: ZSLM | AC55: 10950 | AD55: 30 | AE55: 0 | AF55: =_xlfn.CONCAT(AG55," years ",AH55," days") -> 1 years 62 days | AG55: 1 | AH55: 62 | AI55: 153400 | AJ55: 5982 | AK55: 2025 | AL55: 2535.5525
A56: IN01 | B56: 1131404968 | E56: 0 | F56: Factory Building | G56: 9001 | H56: 9001000019 | I56: Buildings & Admin | J56: 1202010202 | L56: B/NO. 04 DT: 09.09.23 OF JAI MATA CONSTRUCTI-55 | M56: ON BOOKED FOR HT YARD 2500 KVA AREA WALL BREAKIN | O56: 1 | P56: EA | Q56: X | S56: 45231 | T56: 45231 | Y56: 2023 | Z56: 54042 | AA56: 01 | AB56: ZSLM | AC56: 10950 | AD56: 30 | AE56: 0 | AF56: =_xlfn.CONCAT(AG56," years ",AH56," days") -> 1 years 62 days | AG56: 1 | AH56: 62 | AI56: 54042 | AJ56: 2107 | AK56: 2025 | AL56: 893.68822
A57: IN01 | B57: 1131404969 | E57: 0 | F57: Factory Building | G57: 9001 | H57: 9001000019 | I57: Buildings & Admin | J57: 1202010202 | L57: B/NO. 05 DT: 11.09.23 OF JAI MATA CONSTRUCTI-56 | M57: ON BOOKED FOR ROAD EXCAVATION , RCC 200 MM THIK | O57: 1 | P57: EA | Q57: X | S57: 45231 | T57: 45231 | Y57: 2023 | Z57: 3211253 | AA57: 01 | AB57: ZSLM | AC57: 10950 | AD57: 30 | AE57: 0 | AF57: =_xlfn.CONCAT(AG57," years ",AH57," days") -> 1 years 62 days | AG57: 1 | AH57: 62 | AI57: 3211253 | AJ57: 125224 | AK57: 2025 | AL57: 53081.189
A58: IN01 | B58: 1131404970 | E58: 0 | F58: Factory Building | G58: 9001 | H58: 9001000019 | I58: Buildings & Admin | J58: 1202010202 | L58: B/NO. BILL/23-24/19 DT: 01.10.23 OF PK ENTER-57 | M58: PRISES BOOEKD FOR CIVIL WORK AGST PO SMPOCG/23-2 | O58: 1 | P58: EA | Q58: X | S58: 45231 | T58: 45231 | Y58: 2023 | Z58: 111523 | AA58: 01 | AB58: ZSLM | AC58: 10950 | AD58: 30 | AE58: 0 | AF58: =_xlfn.CONCAT(AG58," years ",AH58," days") -> 1 years 62 days | AG58: 1 | AH58: 62 | AI58: 111523 | AJ58: 4349 | AK58: 2025 | AL58: 1843.3273
A59: IN01 | B59: 1131404971 | E59: 0 | F59: Factory Building | G59: 9001 | H59: 9001000019 | I59: Buildings & Admin | J59: 1202010202 | L59: B/NO. 08 DT: 05.10.23 OF JAI MATA CONSTRUCTI-58 | M59: ON BOOKED FOR ROAD EXCAVATION , GSB FILLING , ST | O59: 1 | P59: EA | Q59: X | S59: 45231 | T59: 45231 | Y59: 2023 | Z59: 625968 | AA59: 01 | AB59: ZSLM | AC59: 10950 | AD59: 30 | AE59: 0 | AF59: =_xlfn.CONCAT(AG59," years ",AH59," days") -> 1 years 62 days | AG59: 1 | AH59: 62 | AI59: 625968 | AJ59: 24410 | AK59: 2025 | AL59: 10346.945
A60: IN01 | B60: 1131404972 | E60: 0 | F60: Factory Building | G60: 9001 | H60: 9001000019 | I60: Buildings & Admin | J60: 1202010202 | L60: B/NO. 354/23-24 DT: 06.10.23 OF LAXMI ELE BO-59 | M60: OKED FOR PU FLOORING AGST PO SMPOCG/23-24/202 DT | O60: 46 | P60: EA | Q60: X | S60: 45231 | T60: 45231 | Y60: 2023 | Z60: 80334 | AA60: 01 | AB60: ZSLM | AC60: 10950 | AD60: 30 | AE60: 0 | AF60: =_xlfn.CONCAT(AG60," years ",AH60," days") -> 1 years 62 days | AG60: 1 | AH60: 62 | AI60: 80334 | AJ60: 3133 | AK60: 2025 | AL60: 1327.5545
A61: IN01 | B61: 1131404973 | E61: 0 | F61: Factory Building | G61: 9001 | H61: 9001000019 | I61: Buildings & Admin | J61: 1202010202 | L61: B/NO. 053 DT: 16.10.23 OF GRACE ENGINEERING-60 | M61: BOOKED FOR HAND RAILING MAKING OF UTILITY AGTS | O61: 1 | P61: EA | Q61: X | S61: 45231 | T61: 45231 | Y61: 2023 | Z61: 99120 | AA61: 01 | AB61: ZSLM | AC61: 10950 | AD61: 30 | AE61: 0 | AF61: =_xlfn.CONCAT(AG61," years ",AH61," days") -> 1 years 62 days | AG61: 1 | AH61: 62 | AI61: 99120 | AJ61: 3865 | AK61: 2025 | AL61: 1638.6493
A62: IN01 | B62: 1131405014 | E62: 0 | F62: Factory Building | G62: 9001 | H62: 9001000020 | I62: Buildings & Admin | J62: 1202010202 | L62: BEING T/F THROUGH J/V AGST B/NO. S-123/2023--61 | M62: 24 DT: 10.10.23 OF PRAGMATIC HVAC BOOKED FOR PUR | O62: 67 | P62: EA | Q62: X | S62: 45261 | T62: 45261 | Y62: 2023 | Z62: 100327 | AA62: 01 | AB62: ZSLM | AC62: 10950 | AD62: 30 | AE62: 0 | AF62: =_xlfn.CONCAT(AG62," years ",AH62," days") -> 1 years 32 days | AG62: 1 | AH62: 32 | AI62: 100327 | AJ62: 3637 | AK62: 2025 | AL62: 1658.7996
...
